<?xml version="1.0" ?>

<robot name="talos" xmlns:xacro="http://www.ros.org/wiki/xacro">
  <material name="grey">
    <color rgba="0.2 0.2 0.2 1.0"/>
  </material>
  
  <material name="yellow">
    <color rgba="1 1 0 1.0"/>
  </material>
  
  <gazebo reference="link_chassis">
    <material>Gazebo/DarkGrey</material>
  </gazebo>
  <gazebo reference="link_leftwheel">
    <material>Gazebo/Black</material>
  </gazebo>
  <gazebo reference="link_rightwheel">
    <material>Gazebo/Black</material>
  </gazebo>
  <gazebo reference="link_lasersensor">
    <material>Gazebo/Yellow</material>
  </gazebo>

  <gazebo>
    <plugin filename="libgazebo_ros_diff_drive.so" name="differential_drive_controller">
      <legacyMode>false</legacyMode>
      <alwaysOn>true</alwaysOn>
      <updateRate>20</updateRate>
      <leftJoint>joint_leftwheel</leftJoint>
      <rightJoint>joint_rightwheel</rightJoint>
      <wheelSeparation>0.2</wheelSeparation>
      <wheelDiameter>0.1</wheelDiameter>
      <torque>0.01</torque>
      <commandTopic>cmd_vel</commandTopic>
      <odometryTopic>odom</odometryTopic>
      <odometryFrame>odom</odometryFrame>
      <robotBaseFrame>link_chassis</robotBaseFrame>
    </plugin>
  </gazebo>

<gazebo reference="link_lasersensor">
    <sensor type="ray" name="head_hokuyo_sensor">
      <pose>0 0 0 0 0 0</pose>
      <visualize>false</visualize>
      <update_rate>20</update_rate>
      <ray>
        <scan>
          <horizontal>
            <samples>720</samples>
            <resolution>1</resolution>
            <min_angle>-1.570796</min_angle>
            <max_angle>1.570796</max_angle>
          </horizontal>
        </scan>
        <range>
          <min>0.10</min>
          <max>10.0</max>
          <resolution>0.01</resolution>
        </range>
        <noise>
          <type>gaussian</type>
          <mean>0.0</mean>
          <stddev>0.01</stddev>
        </noise>
      </ray>
      <plugin name="gazebo_ros_head_hokuyo_controller" filename="libgazebo_ros_laser.so">
        <topicName>/talos/laser/scan</topicName>
        <frameName>link_lasersensor</frameName>
      </plugin>
    </sensor>
  </gazebo>

  <link name="link_chassis">
    <!-- pose -->
    <!--  x y   z roll pitch yaw-->
    <pose>0 0 0.1    0     0   0</pose>
    <!-- inertial -->
    <inertial>
      <!--   3 Kgr -->
      <mass value="3"/>
      <!-- same origin as the pose-->
      <origin rpy="0 0 0" xyz="0 0 0.1"/>
      <!-- ixx= mass*(length*length+height*height)/12
             iyy= mass*(width*width+height*height)/12
             izz= mass*(width*width+length*length)/12 -->
      <inertia ixx="0.0109" ixy="0" ixz="0"
               iyy="0.0234" iyz="0"
               izz="0.0325"/>
    </inertial>
    <!-- body -->
    <collision name="collision_chassis">
      <geometry>
        <box size="0.30 0.20 0.06"/>
      </geometry>
    </collision>
    <visual>
      <origin rpy="0 0 0" xyz="0 0 0"/>
      <geometry>
        <box size="0.30 0.20 0.06"/>
      </geometry>
      <material name="grey"/>
    </visual>
    <!-- thirdwheel -->
    <collision name="thirdwheel_collision">
      <origin rpy=" 0 0 0" xyz="0.1 0 -0.03"/>
      <geometry>
        <sphere radius="0.02"/>
      </geometry>
      <surface>
        <friction>
          <ode>
            <!-- no friction -->
            <mu>0</mu>
            <mu2>0</mu2>
            <slip1>1.0</slip1>
            <slip2>1.0</slip2>
          </ode>
        </friction>
      </surface>
    </collision>
    <visual name="thirdwheel_visual">
      <origin rpy=" 0 0 0" xyz="0.1 0 -0.03"/>
      <geometry>
        <sphere radius="0.02"/>
      </geometry>
    </visual>
  </link>
  

<link name="link_lasersensor">
    <inertial>
        <origin xyz="0 0 0" rpy="0 0 0" />
        <mass value="1" />
        <!-- ixx= mass*(3*radius*radius+length*length)/12
             iyy= mass*(3*radius*radius+length*length)/12
             izz= mass*(radius*radius)/2 -->
        <inertia  ixx="0.00013333333" ixy = "0" ixz = "0"
            iyy="0.00013333333" iyz = "0"
            izz="0.000125" />
    </inertial>

    <visual>
        <origin xyz="0 0 0" rpy="0 0 0" />
        <geometry>
        <cylinder radius="0.02" length="0.02"/>
        </geometry>
        <material name="yellow" />
    </visual>

    <collision>
        <origin xyz="0 0 0" rpy="0 0 0"/>
        <geometry>
        <cylinder radius="0.02" length="0.02"/>
        </geometry>
    </collision>
    </link>

    <joint name="joint_lasersensor" type="fixed">
    <origin xyz="0.15 0 0.05" rpy="0 0 0"/>
    <parent link="link_chassis"/>
    <child link="link_lasersensor"/>
  </joint>

  <link name="link_rightwheel">
    <inertial>
      <mass value="0.1"/>
      <origin rpy="0 1.5707 1.5707" xyz="0 0 0"/>
      <inertia ixx="0.00006583333" ixy="0" ixz="0"
               iyy="0.00006583333" iyz="0"
               izz="0.000125"/>
    </inertial>
    <collision name="link_rightwheel_collision">
      <origin rpy="0 1.5707 1.5707" xyz="0 0 0"/>
      <geometry>
        <cylinder length="0.02" radius="0.05"/>
      </geometry>
    </collision>
    <visual name="link_rightwheel_visual">
      <origin rpy="0 1.5707 1.5707" xyz="0 0 0"/>
      <geometry>
        <cylinder length="0.02" radius="0.05"/>
      </geometry>
    </visual>
  </link>
  
  <joint name="joint_rightwheel" type="continuous">
    <origin rpy="0 0 0" xyz="-0.05 0.10 0"/>
    <child link="link_rightwheel"/>
    <parent link="link_chassis"/>
    <axis rpy="0 0 0" xyz="0 1 0"/>
    <limit effort="10000" velocity="1000"/>
    <joint_properties damping="1.0" friction="1.0"/>
  </joint>
  
  <link name="link_leftwheel">
    <inertial>
      <mass value="0.2"/>
      <origin rpy="0 1.5707 1.5707" xyz="0 0 0"/>
      <inertia ixx="0.00006583333" ixy="0" ixz="0" 
               iyy="0.00006583333" iyz="0"
               izz="0.001"/>
    </inertial>
    <collision name="link_leftwheel_collision">
      <origin rpy="0 1.5707 1.5707" xyz="0 0 0"/>
      <geometry>
        <cylinder length="0.02" radius="0.05"/>
      </geometry>
    </collision>
    <visual name="link_leftwheel_visual">
      <origin rpy="0 1.5707 1.5707" xyz="0 0 0"/>
      <geometry>
        <cylinder length="0.02" radius="0.05"/>
      </geometry>
    </visual>
  </link>
  
  <joint name="joint_leftwheel" type="continuous">
    <origin rpy="0 0 0" xyz="-0.05 -0.10 0"/>
    <child link="link_leftwheel"/>
    <parent link="link_chassis"/>
    <axis rpy="0 0 0" xyz="0 1 0"/>
    <limit effort="10000" velocity="1000"/>
    <joint_properties damping="1.0" friction="1.0"/>
  </joint>
</robot>